Workbook
Name Champion: Scores!$C$10
Name ClipHigh: Settings!$C$10
Name ClipLow: Settings!$C$9
Name FcChosen: Forecast!$H$14:$H$21
Name FcMonths: Forecast!$B$14:$B$21
Name Horizon: Settings!$C$6
Name HWOffsets: HW_Python!$B$6:$B$37
Name HWOld: HW_Python!$C$42:$C$47
Name HWOldOffsets: HW_Python!$B$42:$B$47
Name HWProd: HW_Python!$C$52:$C$59
Name HWTable: HW_Python!$C$6:$J$37
Name LastMonth: Settings!$C$12
Name LogSales: Data!$E$7:$E$70
Name Margin: Data!$D$7:$D$70
Name MaxTests: Settings!$C$13
Name MinTrain: Settings!$C$8
Name Months: Data!$B$7:$B$70
Name NMonths: Settings!$C$11
Name Origins: Settings!$C$7
Name RowIdx: Data!$A$7:$A$70
Name Sales: Data!$C$7:$C$70
Name Season: Settings!$C$5
Name TestsUsed: Settings!$C$14

Sheet Guide
B1: TheLook monthly sales forecast, from start to end, in Excel
B3: This workbook rebuilds the whole forecast from src/forecasting.py with live Excel formulas, so you can follow every number from the raw monthly sales to the final answer.
B4: The question it answers: what will net sales be from May to December 2024, which method should we trust, and will the business land its plan?
B5: Work through the tabs from left to right. Each tab is one step, and each step only uses results from the steps before it.
B7: The flow
B8: Step | C8: Tab | D8: Question it answers | E8: Key Excel technique
B9: 1 | C9: Data | D9: What happened? 64 complete months of net sales. | E9: Named ranges (Sales, Months), LN, YoY growth
B10: 2 | C10: Settings | D10: Which numbers does the method depend on? | E10: One labelled cell per assumption, referenced by name
B11: 3 | C11: OneTest | D11: How does one practice test work, month by month? | E11: INDEX on a moving position, FORECAST.ETS, a chart that updates
B12: 4 | C12: Backtest | D12: Repeat the test 24 times, 8 months each: 192 checks. | E12: One row of formulas dragged down 256 rows; ABS errors
B13: 5 | C13: Scores | D13: Which model is most accurate over the full horizon? | E13: AVERAGEIFS, MAXIFS, RANK, INDEX/MATCH for the champion
B14: 6 | C14: OldDesign | D14: Why the first version (6 checks, 1 month ahead) was not enough. | E14: Same formulas, smaller test, side-by-side comparison
B15: 7 | C15: Forecast | D15: What does the champion forecast for May to December 2024? | E15: EDATE, the drift clip MIN(MAX()), choosing a column by MATCH
B16: 8 | C16: Scenarios | D16: What range should we plan for? | E16: Multipliers and margin assumptions from Settings
B17: 9 | C17: CountrySplit | D17: How much of the forecast belongs to each country? | E17: Trailing 6-month shares; a reconciliation row that must be 0
B18: 10 | C18: VsPlan | D18: Will we hit the plan? | E18: Actual if known, otherwise forecast; achievement %
B19: 11 | C19: Checks | D19: Do the Excel results match the Python pipeline? | E19: PASS/CHECK tests against the saved Python numbers
... B21: ref | C21: HW_Python | D21: Holt-Winters predictions computed in Python (statsmodels). | E21: Reference values used by tabs 3 to 7
B23: Colour legend
C24: Blue text | D24: A typed-in value (an input). Change it and everything downstream recalculates.
C25: Black text | D25: A formula calculated in this workbook.
C26: Green text | D26: A formula that simply pulls a result from another tab.
C27: Grey fill | D27: A value calculated in Python and pasted in (Holt-Winters only).
C28: Yellow fill | D28: Try changing this cell to see the effect.
C29: Green fill | D29: A key result.
B31: Experiments to try
C32: 1. | D32: OneTest!C5: change the test number from 24 to 1. The table and chart show a different 8-month practice test.
C33: 2. | D33: Settings!C7: change 'Tests requested' to 6, 12 or 32. Scores shows that drift wins every time.
C34: 3. | D34: Settings!C10: change the upper drift clip from 2.5 to 3. The real forecast rises about 14% and VsPlan changes.
C35: 4. | D35: Settings rows 18 to 20: change the scenario multipliers or margin changes and watch Scenarios.
B37: Limits to keep in mind
C38: • | D38: TheLook is a synthetic dataset: growth is far smoother than real retail, so the 8% error shows the method, not an accuracy promise.
C39: • | D39: The plan is constructed (TheLook ships no budget), so 'achievement vs plan' is a demonstration.
C40: • | D40: Excel cannot refit Holt-Winters exactly like Python's statsmodels, so its predictions are pasted in (HW_Python). OneTest shows Excel's closest built-in, FORECAST.ETS.
C41: • | D41: Changing Horizon or Season in Settings would need the Backtest rows rebuilt; keep them at 8 and 12.

Sheet Data
A1: Step 1 · Data: monthly net sales
A2: The only input the forecast needs: net sales for every complete month, January 2019 to April 2024.
A3: Source: mart.sales_monthly in artifacts/thelook_analytics.duckdb, filtered to is_complete_month = 1.
A5: Position in the series (1 = first month). | B5: Calendar month. | C5: Net sales after cancellations and returns. | D5: Net profit ÷ net sales. Used only for scenarios. | E5: Natural log of net sales. Doubling adds about 0.69. | F5: This month ÷ same month last year. Around 2× means sales doubled.
A6: Row # | B6: Month | C6: Net sales ($) | D6: Net margin rate | E6: log(net sales) | F6: YoY growth (×)
A7: =ROW()-ROW($A$6) -> 1 | B7: 43466 | C7: 1035.64 | D7: 0.54676844 | E7: =LN(C7) -> 6.9427749 | F7: =IF(A7>Season,C7/INDEX(Sales,A7-Season),"")
A8: =ROW()-ROW($A$6) -> 2 | B8: 43497 | C8: 1826.26 | D8: 0.4939079 | E8: =LN(C8) -> 7.5100254 | F8: =IF(A8>Season,C8/INDEX(Sales,A8-Season),"")
A9: =ROW()-ROW($A$6) -> 3 | B9: 43525 | C9: 5955.73 | D9: 0.52384017 | E9: =LN(C9) -> 8.6921091 | F9: =IF(A9>Season,C9/INDEX(Sales,A9-Season),"")
A10: =ROW()-ROW($A$6) -> 4 | B10: 43556 | C10: 7347.19 | D10: 0.49674261 | E10: =LN(C10) -> 8.9020732 | F10: =IF(A10>Season,C10/INDEX(Sales,A10-Season),"")
A11: =ROW()-ROW($A$6) -> 5 | B11: 43586 | C11: 8589.69 | D11: 0.53269492 | E11: =LN(C11) -> 9.0583179 | F11: =IF(A11>Season,C11/INDEX(Sales,A11-Season),"")
A12: =ROW()-ROW($A$6) -> 6 | B12: 43617 | C12: 10800.88 | D12: 0.52208276 | E12: =LN(C12) -> 9.2873829 | F12: =IF(A12>Season,C12/INDEX(Sales,A12-Season),"")
A13: =ROW()-ROW($A$6) -> 7 | B13: 43647 | C13: 13378.13 | D13: 0.51199317 | E13: =LN(C13) -> 9.5013766 | F13: =IF(A13>Season,C13/INDEX(Sales,A13-Season),"")
A14: =ROW()-ROW($A$6) -> 8 | B14: 43678 | C14: 15560.66 | D14: 0.52667438 | E14: =LN(C14) -> 9.6525012 | F14: =IF(A14>Season,C14/INDEX(Sales,A14-Season),"")
A15: =ROW()-ROW($A$6) -> 9 | B15: 43709 | C15: 16565.28 | D15: 0.52004393 | E15: =LN(C15) -> 9.7150642 | F15: =IF(A15>Season,C15/INDEX(Sales,A15-Season),"")
A16: =ROW()-ROW($A$6) -> 10 | B16: 43739 | C16: 20219.63 | D16: 0.52884584 | E16: =LN(C16) -> 9.9144092 | F16: =IF(A16>Season,C16/INDEX(Sales,A16-Season),"")
A17: =ROW()-ROW($A$6) -> 11 | B17: 43770 | C17: 22429.33 | D17: 0.51874837 | E17: =LN(C17) -> 10.018125 | F17: =IF(A17>Season,C17/INDEX(Sales,A17-Season),"")
A18: =ROW()-ROW($A$6) -> 12 | B18: 43800 | C18: 24593.15 | D18: 0.52347827 | E18: =LN(C18) -> 10.110223 | F18: =IF(A18>Season,C18/INDEX(Sales,A18-Season),"")
... A70: =ROW()-ROW($A$6) -> 64 | B70: 45383 | C70: 550157.88 | D70: 0.51848983 | E70: =LN(C70) -> 13.217961 | F70: =IF(A70>Season,C70/INDEX(Sales,A70-Season),"") -> 2.8483458
A72: Excluded: 2024-05 is incomplete (6,556 orders so far vs 8,703 in April 2024). Including it would look like a sales collapse and corrupt both the backtest and the forecast start.
A73: Values are typed in (blue) from the warehouse; everything after this tab is a formula.

Sheet Settings
A1: Step 2 · Settings: every number the method depends on
A2: Each assumption lives in one labelled cell and is used by name everywhere else (for example =ClipHigh).
A3: Change a yellow cell and the whole workbook recalculates.
B4: Setting | C4: Value | D4: What it means | E4: Python name (src/forecasting.py)
B5: Season length (months) | C5: 12 | D5: The sales pattern repeats every 12 months. | E5: SEASONAL_PERIODS (line 80)
B6: Forecast horizon (months) | C6: 8 | D6: How far ahead each forecast runs: May to Dec 2024 = 8. Structural: keep at 8. | E6: horizon in run()
B7: Tests requested | C7: 24 | D7: How many practice tests (starting points) to run. Try 6, 12 or 32. | E7: BACKTEST_ORIGINS (line 87)
B8: Minimum training months | C8: =2*Season+1 -> 25 | D8: Holt-Winters needs two full seasons plus one month of history. | E8: MIN_TRAIN_MONTHS (line 88)
B9: Drift clip, lower | C9: 0.5 | D9: Growth ratio is never allowed below this. | E9: np.clip(drift, 0.5, 2.5)
B10: Drift clip, upper | C10: 2.5 | D10: Growth ratio is never allowed above this. Try 3.0. | E10: np.clip(drift, 0.5, 2.5)
B11: Months of data | C11: =COUNT(Sales) -> 64 | D11: Complete months in the Data tab. | E11: len(series)
B12: Last actual month | C12: =INDEX(Months,NMonths) -> 45383 | D12: The forecast starts the month after this. | E12: last_actual_month
B13: Most tests the data allows | C13: =NMonths-MinTrain-Horizon+1 -> 32 | D13: Each test needs MinTrain months before it and Horizon months after it. | E13: len(series) - MIN_TRAIN_MONTHS
B14: Tests actually used | C14: =MIN(Origins,MaxTests) -> 24 | D14: The latest tests are kept; earlier ones are skipped. | E14: offsets in backtest()
B16: Scenario assumptions (used in the Scenarios tab)
B17: Scenario | C17: Volume multiplier | D17: Margin change (pp) | E17: Assumption
B18: Base | C18: 1 | D18: 0 | E18: Current trend continues; no change to pricing or promotion intensity.
B19: Upside | C19: 1.1 | D19: 0.5 | E19: Peak-season sell-through runs 10% ahead with a modest mix benefit.
B20: Downside | C20: 0.9 | D20: -2 | E20: Demand softens 10% and clearing aged stock costs 2 points of margin.
B22: Source: SCENARIOS in src/forecasting.py (lines 90–106). The downside margin hit links to 273K units of stock aged 181+ days.

Sheet OneTest
A1: Step 3 · One practice test, by hand
A2: Pretend 'today' is the end of a past month, hide everything after it, forecast the next 8 months, then compare with what really happened.
A3: Pick a test number in the yellow cell. Every number below, and the chart, follows.
B5: Pick a test number (1 = earliest kept) | C5: 24
B6: Offset (months hidden at the end) | C6: =TestsUsed+Horizon-C5 -> 8 | D6: Python: offset in backtest(). Test 24 hides the last 8 months.
B7: History months the model sees | C7: =NMonths-C6 -> 56 | D7: series.iloc[:-offset] keeps this many months, always starting Jan 2019.
B8: Last month the model sees ('today') | C8: =INDEX(Months,C7) -> 45139
B9: First forecast month | C9: =INDEX(Months,C7+1) -> 45170
B11: The drift growth ratio for this test
B12: Latest month the model sees | C12: =INDEX(Sales,C7) -> 246129.77 | D12: =INDEX(Months,C7) -> 45139
B13: Same month one year earlier | C13: =INDEX(Sales,C7-Season) -> 142612.79 | D13: =INDEX(Months,C7-Season) -> 44774
B14: Raw drift = latest ÷ year earlier | C14: =C12/C13 -> 1.7258604
B15: Drift after clip = MIN(MAX(raw, low), high) | C15: =MIN(MAX(C14,ClipLow),ClipHigh) -> 1.7258604 | D15: Every drift forecast below = same month last year × this number.
B17: 1 = next month, 8 = furthest. | C17: The hidden month being forecast. | D17: What really happened (hidden from the model). | E17: Copy the same month last year: INDEX(Sales, row − 12). | F17: Seasonal naive × drift after clip. | G17: Looked up from HW_Python by offset and step. | H17: Excel's own exponential smoothing on log(sales), then EXP back to dollars. | I17: |forecast − actual| ÷ actual
B18: Step | C18: Target month | D18: Actual | E18: Seasonal naive | F18: Drift | G18: Holt-Winters (Python) | H18: Excel FORECAST.ETS (log) | I18: Error naive | J18: Error drift | K18: Error HW | L18: Error ETS
B19: =ROW()-ROW($B$18) -> 1 | C19: =INDEX(Months,$C$7+B19) -> 45170 | D19: =INDEX(Sales,$C$7+B19) -> 261138.52 | E19: =INDEX(Sales,$C$7+B19-Season) -> 137519.58 | F19: =E19*$C$15 -> 237339.6 | G19: =INDEX(HWTable,MATCH($C$6,HWOffsets,0),B19) -> 247168.28 | H19: =EXP(_xlfn.FORECAST.ETS($C$7+B19,OFFSET(LogSales,0,0,$C$7),OFFSET(RowIdx,0,0,$C$7),Season)) -> 248264.84 | I19: =ABS(E19-$D19)/$D19 -> 0.47338455 | J19: =ABS(F19-$D19)/$D19 -> 0.091135231 | K19: =ABS(G19-$D19)/$D19 -> 0.053497415 | L19: =ABS(H19-$D19)/$D19 -> 0.049298289
B20: =ROW()-ROW($B$18) -> 2 | C20: =INDEX(Months,$C$7+B20) -> 45200 | D20: =INDEX(Sales,$C$7+B20) -> 279981.62 | E20: =INDEX(Sales,$C$7+B20-Season) -> 152485.03 | F20: =E20*$C$15 -> 263167.88 | G20: =INDEX(HWTable,MATCH($C$6,HWOffsets,0),B20) -> 285815.14 | H20: =EXP(_xlfn.FORECAST.ETS($C$7+B20,OFFSET(LogSales,0,0,$C$7),OFFSET(RowIdx,0,0,$C$7),Season)) -> 284826.64 | I20: =ABS(E20-$D20)/$D20 -> 0.45537486 | J20: =ABS(F20-$D20)/$D20 -> 0.060053019 | K20: =ABS(G20-$D20)/$D20 -> 0.020835373 | L20: =ABS(H20-$D20)/$D20 -> 0.017304791
B21: =ROW()-ROW($B$18) -> 3 | C21: =INDEX(Months,$C$7+B21) -> 45231 | D21: =INDEX(Sales,$C$7+B21) -> 298467.68 | E21: =INDEX(Sales,$C$7+B21-Season) -> 155504.04 | F21: =E21*$C$15 -> 268378.27 | G21: =INDEX(HWTable,MATCH($C$6,HWOffsets,0),B21) -> 313887.29 | H21: =EXP(_xlfn.FORECAST.ETS($C$7+B21,OFFSET(LogSales,0,0,$C$7),OFFSET(RowIdx,0,0,$C$7),Season)) -> 308928.71 | I21: =ABS(E21-$D21)/$D21 -> 0.47899203 | J21: =ABS(F21-$D21)/$D21 -> 0.10081297 | K21: =ABS(G21-$D21)/$D21 -> 0.051662594 | L21: =ABS(H21-$D21)/$D21 -> 0.035049112
B22: =ROW()-ROW($B$18) -> 4 | C22: =INDEX(Months,$C$7+B22) -> 45261 | D22: =INDEX(Sales,$C$7+B22) -> 326301.66 | E22: =INDEX(Sales,$C$7+B22-Season) -> 160734.27 | F22: =E22*$C$15 -> 277404.92 | G22: =INDEX(HWTable,MATCH($C$6,HWOffsets,0),B22) -> 333921.42 | H22: =EXP(_xlfn.FORECAST.ETS($C$7+B22,OFFSET(LogSales,0,0,$C$7),OFFSET(RowIdx,0,0,$C$7),Season)) -> 315138.53 | I22: =ABS(E22-$D22)/$D22 -> 0.50740591 | J22: =ABS(F22-$D22)/$D22 -> 0.14985135 | K22: =ABS(G22-$D22)/$D22 -> 0.023351898 | L22: =ABS(H22-$D22)/$D22 -> 0.034211067
B23: =ROW()-ROW($B$18) -> 5 | C23: =INDEX(Months,$C$7+B23) -> 45292 | D23: =INDEX(Sales,$C$7+B23) -> 348737.74 | E23: =INDEX(Sales,$C$7+B23-Season) -> 188680.17 | F23: =E23*$C$15 -> 325635.64 | G23: =INDEX(HWTable,MATCH($C$6,HWOffsets,0),B23) -> 415827.74 | H23: =EXP(_xlfn.FORECAST.ETS($C$7+B23,OFFSET(LogSales,0,0,$C$7),OFFSET(RowIdx,0,0,$C$7),Season)) -> 375282.61 | I23: =ABS(E23-$D23)/$D23 -> 0.45896257 | J23: =ABS(F23-$D23)/$D23 -> 0.066244916 | K23: =ABS(G23-$D23)/$D23 -> 0.19237951 | L23: =ABS(H23-$D23)/$D23 -> 0.076116997
B24: =ROW()-ROW($B$18) -> 6 | C24: =INDEX(Months,$C$7+B24) -> 45323 | D24: =INDEX(Sales,$C$7+B24) -> 381972.6 | E24: =INDEX(Sales,$C$7+B24-Season) -> 167409.85 | F24: =E24*$C$15 -> 288926.03 | G24: =INDEX(HWTable,MATCH($C$6,HWOffsets,0),B24) -> 395880.78 | H24: =EXP(_xlfn.FORECAST.ETS($C$7+B24,OFFSET(LogSales,0,0,$C$7),OFFSET(RowIdx,0,0,$C$7),Season)) -> 326529.97 | I24: =ABS(E24-$D24)/$D24 -> 0.56172288 | J24: =ABS(F24-$D24)/$D24 -> 0.24359487 | K24: =ABS(G24-$D24)/$D24 -> 0.036411469 | L24: =ABS(H24-$D24)/$D24 -> 0.14514818
B25: =ROW()-ROW($B$18) -> 7 | C25: =INDEX(Months,$C$7+B25) -> 45352 | D25: =INDEX(Sales,$C$7+B25) -> 441334.21 | E25: =INDEX(Sales,$C$7+B25-Season) -> 184777.9 | F25: =E25*$C$15 -> 318900.86 | G25: =INDEX(HWTable,MATCH($C$6,HWOffsets,0),B25) -> 540121.06 | H25: =EXP(_xlfn.FORECAST.ETS($C$7+B25,OFFSET(LogSales,0,0,$C$7),OFFSET(RowIdx,0,0,$C$7),Season)) -> 391006.86 | I25: =ABS(E25-$D25)/$D25 -> 0.58131979 | J25: =ABS(F25-$D25)/$D25 -> 0.27741639 | K25: =ABS(G25-$D25)/$D25 -> 0.22383683 | L25: =ABS(H25-$D25)/$D25 -> 0.11403456
B26: =ROW()-ROW($B$18) -> 8 | C26: =INDEX(Months,$C$7+B26) -> 45383 | D26: =INDEX(Sales,$C$7+B26) -> 550157.88 | E26: =INDEX(Sales,$C$7+B26-Season) -> 193149.96 | F26: =E26*$C$15 -> 333349.87 | G26: =INDEX(HWTable,MATCH($C$6,HWOffsets,0),B26) -> 557020.58 | H26: =EXP(_xlfn.FORECAST.ETS($C$7+B26,OFFSET(LogSales,0,0,$C$7),OFFSET(RowIdx,0,0,$C$7),Season)) -> 429598.53 | I26: =ABS(E26-$D26)/$D26 -> 0.64891903 | J26: =ABS(F26-$D26)/$D26 -> 0.39408326 | K26: =ABS(G26-$D26)/$D26 -> 0.012474055 | L26: =ABS(H26-$D26)/$D26 -> 0.21913591
B27: Average error for this test | I27: =AVERAGE(I19:I26) -> 0.5207602 | J27: =AVERAGE(J19:J26) -> 0.172899 | K27: =AVERAGE(K19:K26) -> 0.076806143 | L27: =AVERAGE(L19:L26) -> 0.086287363
B28: FORECAST.ETS fits the same kind of model as holt_winters_log (trend + seasonality on the log) but picks its own smoothing settings, so its numbers differ from Python's.

Sheet Backtest
A1: Step 4 · Backtest: every practice test, every step
A2: One row = one forecast checked against reality (a fold). Row 9 holds the formulas; rows 10 to 264 are the same formulas dragged down.
A3: All 32 tests the data allows are listed. 'Included' marks the latest ones kept by Settings (24 by default = 192 folds). Grey rows are skipped.
A7: Which of the 32 possible tests. | B7: 1 = next month, 8 = furthest. | C7: Months hidden at the end of the series. | D7: 1 if this test is one of the latest TestsUsed. | E7: Test number as used in the scores. | F7: Months the model learns from (= last training row). | G7: First forecast month of this test. | H7: Row in Data being forecast. | I7: The month being forecast. | J7: What really happened. | K7: Same month last year. | L7: Latest ÷ year-earlier, before the clip. | M7: Raw drift clipped to [low, high]. | N7: Seasonal naive × clipped drift. | O7: From HW_Python (offset, step). | P7: |naive − actual| ÷ actual | Q7: |drift − actual| ÷ actual | R7: |HW − actual| ÷ actual | S7: naive ÷ actual − 1 (keeps the sign) | T7: drift ÷ actual − 1 | U7: HW ÷ actual − 1
A8: Possible test | B8: Step | C8: Offset | D8: Included | E8: Test # | F8: History months | G8: Test starts | H8: Target row | I8: Target month | J8: Actual | K8: Seasonal naive | L8: Raw drift | M8: Clipped drift | N8: Drift forecast | O8: Holt-Winters | P8: Error naive | Q8: Error drift | R8: Error HW | S8: Bias naive | T8: Bias drift | U8: Bias HW
A9: =INT((ROW()-ROW($A$9))/Horizon)+1 -> 1 | B9: =MOD(ROW()-ROW($A$9),Horizon)+1 -> 1 | C9: =(NMonths-MinTrain)-(A9-1) -> 39 | D9: =IF(C9<=TestsUsed+Horizon-1,1,0) -> 0 | E9: =IF(D9=1,TestsUsed+Horizon-C9,"") | F9: =NMonths-C9 -> 25 | G9: =INDEX(Months,F9+1) -> 44228 | H9: =F9+B9 -> 26 | I9: =INDEX(Months,H9) -> 44228 | J9: =INDEX(Sales,H9) -> 56663.07 | K9: =INDEX(Sales,H9-Season) -> 25472.47 | L9: =INDEX(Sales,F9)/INDEX(Sales,F9-Season) -> 2.1413542 | M9: =MIN(MAX(L9,ClipLow),ClipHigh) -> 2.1413542 | N9: =K9*M9 -> 54545.581 | O9: =INDEX(HWTable,MATCH(C9,HWOffsets,0),B9) -> 77188.376 | P9: =ABS(K9-J9)/J9 -> 0.55045729 | Q9: =ABS(N9-J9)/J9 -> 0.037369834 | R9: =ABS(O9-J9)/J9 -> 0.36223426 | S9: =K9/J9-1 -> -0.55045729 | T9: =N9/J9-1 -> -0.037369834 | U9: =O9/J9-1 -> 0.36223426
A10: =INT((ROW()-ROW($A$9))/Horizon)+1 -> 1 | B10: =MOD(ROW()-ROW($A$9),Horizon)+1 -> 2 | C10: =(NMonths-MinTrain)-(A10-1) -> 39 | D10: =IF(C10<=TestsUsed+Horizon-1,1,0) -> 0 | E10: =IF(D10=1,TestsUsed+Horizon-C10,"") | F10: =NMonths-C10 -> 25 | G10: =INDEX(Months,F10+1) -> 44228 | H10: =F10+B10 -> 27 | I10: =INDEX(Months,H10) -> 44256 | J10: =INDEX(Sales,H10) -> 60978.7 | K10: =INDEX(Sales,H10-Season) -> 33801.99 | L10: =INDEX(Sales,F10)/INDEX(Sales,F10-Season) -> 2.1413542 | M10: =MIN(MAX(L10,ClipLow),ClipHigh) -> 2.1413542 | N10: =K10*M10 -> 72382.033 | O10: =INDEX(HWTable,MATCH(C10,HWOffsets,0),B10) -> 160573.4 | P10: =ABS(K10-J10)/J10 -> 0.44567546 | Q10: =ABS(N10-J10)/J10 -> 0.18700518 | R10: =ABS(O10-J10)/J10 -> 1.6332702 | S10: =K10/J10-1 -> -0.44567546 | T10: =N10/J10-1 -> 0.18700518 | U10: =O10/J10-1 -> 1.6332702
A11: =INT((ROW()-ROW($A$9))/Horizon)+1 -> 1 | B11: =MOD(ROW()-ROW($A$9),Horizon)+1 -> 3 | C11: =(NMonths-MinTrain)-(A11-1) -> 39 | D11: =IF(C11<=TestsUsed+Horizon-1,1,0) -> 0 | E11: =IF(D11=1,TestsUsed+Horizon-C11,"") | F11: =NMonths-C11 -> 25 | G11: =INDEX(Months,F11+1) -> 44228 | H11: =F11+B11 -> 28 | I11: =INDEX(Months,H11) -> 44287 | J11: =INDEX(Sales,H11) -> 70861.69 | K11: =INDEX(Sales,H11-Season) -> 34806.27 | L11: =INDEX(Sales,F11)/INDEX(Sales,F11-Season) -> 2.1413542 | M11: =MIN(MAX(L11,ClipLow),ClipHigh) -> 2.1413542 | N11: =K11*M11 -> 74532.552 | O11: =INDEX(HWTable,MATCH(C11,HWOffsets,0),B11) -> 180977.36 | P11: =ABS(K11-J11)/J11 -> 0.508814 | Q11: =ABS(N11-J11)/J11 -> 0.051803198 | R11: =ABS(O11-J11)/J11 -> 1.5539521 | S11: =K11/J11-1 -> -0.508814 | T11: =N11/J11-1 -> 0.051803198 | U11: =O11/J11-1 -> 1.5539521
A12: =INT((ROW()-ROW($A$9))/Horizon)+1 -> 1 | B12: =MOD(ROW()-ROW($A$9),Horizon)+1 -> 4 | C12: =(NMonths-MinTrain)-(A12-1) -> 39 | D12: =IF(C12<=TestsUsed+Horizon-1,1,0) -> 0 | E12: =IF(D12=1,TestsUsed+Horizon-C12,"") | F12: =NMonths-C12 -> 25 | G12: =INDEX(Months,F12+1) -> 44228 | H12: =F12+B12 -> 29 | I12: =INDEX(Months,H12) -> 44317 | J12: =INDEX(Sales,H12) -> 74001.79 | K12: =INDEX(Sales,H12-Season) -> 36725.07 | L12: =INDEX(Sales,F12)/INDEX(Sales,F12-Season) -> 2.1413542 | M12: =MIN(MAX(L12,ClipLow),ClipHigh) -> 2.1413542 | N12: =K12*M12 -> 78641.383 | O12: =INDEX(HWTable,MATCH(C12,HWOffsets,0),B12) -> 201004.15 | P12: =ABS(K12-J12)/J12 -> 0.50372727 | Q12: =ABS(N12-J12)/J12 -> 0.062695682 | R12: =ABS(O12-J12)/J12 -> 1.7162066 | S12: =K12/J12-1 -> -0.50372727 | T12: =N12/J12-1 -> 0.062695682 | U12: =O12/J12-1 -> 1.7162066
A13: =INT((ROW()-ROW($A$9))/Horizon)+1 -> 1 | B13: =MOD(ROW()-ROW($A$9),Horizon)+1 -> 5 | C13: =(NMonths-MinTrain)-(A13-1) -> 39 | D13: =IF(C13<=TestsUsed+Horizon-1,1,0) -> 0 | E13: =IF(D13=1,TestsUsed+Horizon-C13,"") | F13: =NMonths-C13 -> 25 | G13: =INDEX(Months,F13+1) -> 44228 | H13: =F13+B13 -> 30 | I13: =INDEX(Months,H13) -> 44348 | J13: =INDEX(Sales,H13) -> 74855.45 | K13: =INDEX(Sales,H13-Season) -> 36275.65 | L13: =INDEX(Sales,F13)/INDEX(Sales,F13-Season) -> 2.1413542 | M13: =MIN(MAX(L13,ClipLow),ClipHigh) -> 2.1413542 | N13: =K13*M13 -> 77679.015 | O13: =INDEX(HWTable,MATCH(C13,HWOffsets,0),B13) -> 224012.42 | P13: =ABS(K13-J13)/J13 -> 0.51539066 | Q13: =ABS(N13-J13)/J13 -> 0.037720237 | R13: =ABS(O13-J13)/J13 -> 1.9925999 | S13: =K13/J13-1 -> -0.51539066 | T13: =N13/J13-1 -> 0.037720237 | U13: =O13/J13-1 -> 1.9925999
A14: =INT((ROW()-ROW($A$9))/Horizon)+1 -> 1 | B14: =MOD(ROW()-ROW($A$9),Horizon)+1 -> 6 | C14: =(NMonths-MinTrain)-(A14-1) -> 39 | D14: =IF(C14<=TestsUsed+Horizon-1,1,0) -> 0 | E14: =IF(D14=1,TestsUsed+Horizon-C14,"") | F14: =NMonths-C14 -> 25 | G14: =INDEX(Months,F14+1) -> 44228 | H14: =F14+B14 -> 31 | I14: =INDEX(Months,H14) -> 44378 | J14: =INDEX(Sales,H14) -> 80016.69 | K14: =INDEX(Sales,H14-Season) -> 44275.79 | L14: =INDEX(Sales,F14)/INDEX(Sales,F14-Season) -> 2.1413542 | M14: =MIN(MAX(L14,ClipLow),ClipHigh) -> 2.1413542 | N14: =K14*M14 -> 94810.149 | O14: =INDEX(HWTable,MATCH(C14,HWOffsets,0),B14) -> 275432.9 | P14: =ABS(K14-J14)/J14 -> 0.44666806 | Q14: =ABS(N14-J14)/J14 -> 0.18487966 | R14: =ABS(O14-J14)/J14 -> 2.4421931 | S14: =K14/J14-1 -> -0.44666806 | T14: =N14/J14-1 -> 0.18487966 | U14: =O14/J14-1 -> 2.4421931
A15: =INT((ROW()-ROW($A$9))/Horizon)+1 -> 1 | B15: =MOD(ROW()-ROW($A$9),Horizon)+1 -> 7 | C15: =(NMonths-MinTrain)-(A15-1) -> 39 | D15: =IF(C15<=TestsUsed+Horizon-1,1,0) -> 0 | E15: =IF(D15=1,TestsUsed+Horizon-C15,"") | F15: =NMonths-C15 -> 25 | G15: =INDEX(Months,F15+1) -> 44228 | H15: =F15+B15 -> 32 | I15: =INDEX(Months,H15) -> 44409 | J15: =INDEX(Sales,H15) -> 80303.24 | K15: =INDEX(Sales,H15-Season) -> 46063.2 | L15: =INDEX(Sales,F15)/INDEX(Sales,F15-Season) -> 2.1413542 | M15: =MIN(MAX(L15,ClipLow),ClipHigh) -> 2.1413542 | N15: =K15*M15 -> 98637.627 | O15: =INDEX(HWTable,MATCH(C15,HWOffsets,0),B15) -> 302988.53 | P15: =ABS(K15-J15)/J15 -> 0.42638429 | Q15: =ABS(N15-J15)/J15 -> 0.2283144 | R15: =ABS(O15-J15)/J15 -> 2.7730549 | S15: =K15/J15-1 -> -0.42638429 | T15: =N15/J15-1 -> 0.2283144 | U15: =O15/J15-1 -> 2.7730549
A16: =INT((ROW()-ROW($A$9))/Horizon)+1 -> 1 | B16: =MOD(ROW()-ROW($A$9),Horizon)+1 -> 8 | C16: =(NMonths-MinTrain)-(A16-1) -> 39 | D16: =IF(C16<=TestsUsed+Horizon-1,1,0) -> 0 | E16: =IF(D16=1,TestsUsed+Horizon-C16,"") | F16: =NMonths-C16 -> 25 | G16: =INDEX(Months,F16+1) -> 44228 | H16: =F16+B16 -> 33 | I16: =INDEX(Months,H16) -> 44440 | J16: =INDEX(Sales,H16) -> 84924.86 | K16: =INDEX(Sales,H16-Season) -> 42591.05 | L16: =INDEX(Sales,F16)/INDEX(Sales,F16-Season) -> 2.1413542 | M16: =MIN(MAX(L16,ClipLow),ClipHigh) -> 2.1413542 | N16: =K16*M16 -> 91202.524 | O16: =INDEX(HWTable,MATCH(C16,HWOffsets,0),B16) -> 300603.22 | P16: =ABS(K16-J16)/J16 -> 0.49848548 | Q16: =ABS(N16-J16)/J16 -> 0.07392021 | R16: =ABS(O16-J16)/J16 -> 2.5396375 | S16: =K16/J16-1 -> -0.49848548 | T16: =N16/J16-1 -> 0.07392021 | U16: =O16/J16-1 -> 2.5396375
A17: =INT((ROW()-ROW($A$9))/Horizon)+1 -> 2 | B17: =MOD(ROW()-ROW($A$9),Horizon)+1 -> 1 | C17: =(NMonths-MinTrain)-(A17-1) -> 38 | D17: =IF(C17<=TestsUsed+Horizon-1,1,0) -> 0 | E17: =IF(D17=1,TestsUsed+Horizon-C17,"") | F17: =NMonths-C17 -> 26 | G17: =INDEX(Months,F17+1) -> 44256 | H17: =F17+B17 -> 27 | I17: =INDEX(Months,H17) -> 44256 | J17: =INDEX(Sales,H17) -> 60978.7 | K17: =INDEX(Sales,H17-Season) -> 33801.99 | L17: =INDEX(Sales,F17)/INDEX(Sales,F17-Season) -> 2.2244827 | M17: =MIN(MAX(L17,ClipLow),ClipHigh) -> 2.2244827 | N17: =K17*M17 -> 75191.944 | O17: =INDEX(HWTable,MATCH(C17,HWOffsets,0),B17) -> 117875.02 | P17: =ABS(K17-J17)/J17 -> 0.44567546 | Q17: =ABS(N17-J17)/J17 -> 0.23308538 | R17: =ABS(O17-J17)/J17 -> 0.93305239 | S17: =K17/J17-1 -> -0.44567546 | T17: =N17/J17-1 -> 0.23308538 | U17: =O17/J17-1 -> 0.93305239
A18: =INT((ROW()-ROW($A$9))/Horizon)+1 -> 2 | B18: =MOD(ROW()-ROW($A$9),Horizon)+1 -> 2 | C18: =(NMonths-MinTrain)-(A18-1) -> 38 | D18: =IF(C18<=TestsUsed+Horizon-1,1,0) -> 0 | E18: =IF(D18=1,TestsUsed+Horizon-C18,"") | F18: =NMonths-C18 -> 26 | G18: =INDEX(Months,F18+1) -> 44256 | H18: =F18+B18 -> 28 | I18: =INDEX(Months,H18) -> 44287 | J18: =INDEX(Sales,H18) -> 70861.69 | K18: =INDEX(Sales,H18-Season) -> 34806.27 | L18: =INDEX(Sales,F18)/INDEX(Sales,F18-Season) -> 2.2244827 | M18: =MIN(MAX(L18,ClipLow),ClipHigh) -> 2.2244827 | N18: =K18*M18 -> 77425.947 | O18: =INDEX(HWTable,MATCH(C18,HWOffsets,0),B18) -> 132853.31 | P18: =ABS(K18-J18)/J18 -> 0.508814 | Q18: =ABS(N18-J18)/J18 -> 0.092634778 | R18: =ABS(O18-J18)/J18 -> 0.87482559 | S18: =K18/J18-1 -> -0.508814 | T18: =N18/J18-1 -> 0.092634778 | U18: =O18/J18-1 -> 0.87482559
A19: =INT((ROW()-ROW($A$9))/Horizon)+1 -> 2 | B19: =MOD(ROW()-ROW($A$9),Horizon)+1 -> 3 | C19: =(NMonths-MinTrain)-(A19-1) -> 38 | D19: =IF(C19<=TestsUsed+Horizon-1,1,0) -> 0 | E19: =IF(D19=1,TestsUsed+Horizon-C19,"") | F19: =NMonths-C19 -> 26 | G19: =INDEX(Months,F19+1) -> 44256 | H19: =F19+B19 -> 29 | I19: =INDEX(Months,H19) -> 44317 | J19: =INDEX(Sales,H19) -> 74001.79 | K19: =INDEX(Sales,H19-Season) -> 36725.07 | L19: =INDEX(Sales,F19)/INDEX(Sales,F19-Season) -> 2.2244827 | M19: =MIN(MAX(L19,ClipLow),ClipHigh) -> 2.2244827 | N19: =K19*M19 -> 81694.285 | O19: =INDEX(HWTable,MATCH(C19,HWOffsets,0),B19) -> 147554.68 | P19: =ABS(K19-J19)/J19 -> 0.50372727 | Q19: =ABS(N19-J19)/J19 -> 0.10395011 | R19: =ABS(O19-J19)/J19 -> 0.99393388 | S19: =K19/J19-1 -> -0.50372727 | T19: =N19/J19-1 -> 0.10395011 | U19: =O19/J19-1 -> 0.99393388
A20: =INT((ROW()-ROW($A$9))/Horizon)+1 -> 2 | B20: =MOD(ROW()-ROW($A$9),Horizon)+1 -> 4 | C20: =(NMonths-MinTrain)-(A20-1) -> 38 | D20: =IF(C20<=TestsUsed+Horizon-1,1,0) -> 0 | E20: =IF(D20=1,TestsUsed+Horizon-C20,"") | F20: =NMonths-C20 -> 26 | G20: =INDEX(Months,F20+1) -> 44256 | H20: =F20+B20 -> 30 | I20: =INDEX(Months,H20) -> 44348 | J20: =INDEX(Sales,H20) -> 74855.45 | K20: =INDEX(Sales,H20-Season) -> 36275.65 | L20: =INDEX(Sales,F20)/INDEX(Sales,F20-Season) -> 2.2244827 | M20: =MIN(MAX(L20,ClipLow),ClipHigh) -> 2.2244827 | N20: =K20*M20 -> 80694.558 | O20: =INDEX(HWTable,MATCH(C20,HWOffsets,0),B20) -> 164444.78 | P20: =ABS(K20-J20)/J20 -> 0.51539066 | Q20: =ABS(N20-J20)/J20 -> 0.078005108 | R20: =ABS(O20-J20)/J20 -> 1.1968311 | S20: =K20/J20-1 -> -0.51539066 | T20: =N20/J20-1 -> 0.078005108 | U20: =O20/J20-1 -> 1.1968311
... A264: =INT((ROW()-ROW($A$9))/Horizon)+1 -> 32 | B264: =MOD(ROW()-ROW($A$9),Horizon)+1 -> 8 | C264: =(NMonths-MinTrain)-(A264-1) -> 8 | D264: =IF(C264<=TestsUsed+Horizon-1,1,0) -> 1 | E264: =IF(D264=1,TestsUsed+Horizon-C264,"") -> 24 | F264: =NMonths-C264 -> 56 | G264: =INDEX(Months,F264+1) -> 45170 | H264: =F264+B264 -> 64 | I264: =INDEX(Months,H264) -> 45383 | J264: =INDEX(Sales,H264) -> 550157.88 | K264: =INDEX(Sales,H264-Season) -> 193149.96 | L264: =INDEX(Sales,F264)/INDEX(Sales,F264-Season) -> 1.7258604 | M264: =MIN(MAX(L264,ClipLow),ClipHigh) -> 1.7258604 | N264: =K264*M264 -> 333349.87 | O264: =INDEX(HWTable,MATCH(C264,HWOffsets,0),B264) -> 557020.58 | P264: =ABS(K264-J264)/J264 -> 0.64891903 | Q264: =ABS(N264-J264)/J264 -> 0.39408326 | R264: =ABS(O264-J264)/J264 -> 0.012474055 | S264: =K264/J264-1 -> -0.64891903 | T264: =N264/J264-1 -> -0.39408326 | U264: =O264/J264-1 -> 0.012474055

Sheet Scores
A1: Step 5 · Scores: turn the folds into one score per model
A2: Only included tests count. MAPE = average error size (lower is better). Bias = average error with its sign (negative = forecasts too low).
A3: The champion is the model with the lowest MAPE across all 8 steps, because that is how far ahead the real forecast runs.
B5: Model | C5: MAPE (all 8 steps) | D5: MAPE 1 month ahead | E5: MAPE 8 months ahead | F5: Worst single error | G5: Bias | H5: Tests | I5: Folds | J5: Rank
B6: seasonal_naive | C6: =AVERAGEIFS(Backtest!$P$9:$P$264,Backtest!$D$9:$D$264,1) -> 0.42418045 | D6: =AVERAGEIFS(Backtest!$P$9:$P$264,Backtest!$D$9:$D$264,1,Backtest!$B$9:$B$264,1) -> 0.41659902 | E6: =AVERAGEIFS(Backtest!$P$9:$P$264,Backtest!$D$9:$D$264,1,Backtest!$B$9:$B$264,Horizon) -> 0.44208002 | F6: =_xlfn.MAXIFS(Backtest!$P$9:$P$264,Backtest!$D$9:$D$264,1) -> 0.64891903 | G6: =AVERAGEIFS(Backtest!$S$9:$S$264,Backtest!$D$9:$D$264,1) -> -0.42418045 | H6: =TestsUsed -> 24 | I6: =SUM(Backtest!$D$9:$D$264) -> 192 | J6: =RANK(C6,$C$6:$C$8,1) -> 3
B7: seasonal_naive_drift | C7: =AVERAGEIFS(Backtest!$Q$9:$Q$264,Backtest!$D$9:$D$264,1) -> 0.080024478 | D7: =AVERAGEIFS(Backtest!$Q$9:$Q$264,Backtest!$D$9:$D$264,1,Backtest!$B$9:$B$264,1) -> 0.064570076 | E7: =AVERAGEIFS(Backtest!$Q$9:$Q$264,Backtest!$D$9:$D$264,1,Backtest!$B$9:$B$264,Horizon) -> 0.11529421 | F7: =_xlfn.MAXIFS(Backtest!$Q$9:$Q$264,Backtest!$D$9:$D$264,1) -> 0.39408326 | G7: =AVERAGEIFS(Backtest!$T$9:$T$264,Backtest!$D$9:$D$264,1) -> -0.0071072277 | H7: =TestsUsed -> 24 | I7: =SUM(Backtest!$D$9:$D$264) -> 192 | J7: =RANK(C7,$C$6:$C$8,1) -> 1
B8: holt_winters_log | C8: =AVERAGEIFS(Backtest!$R$9:$R$264,Backtest!$D$9:$D$264,1) -> 0.25975189 | D8: =AVERAGEIFS(Backtest!$R$9:$R$264,Backtest!$D$9:$D$264,1,Backtest!$B$9:$B$264,1) -> 0.082601102 | E8: =AVERAGEIFS(Backtest!$R$9:$R$264,Backtest!$D$9:$D$264,1,Backtest!$B$9:$B$264,Horizon) -> 0.43512759 | F8: =_xlfn.MAXIFS(Backtest!$R$9:$R$264,Backtest!$D$9:$D$264,1) -> 1.6306427 | G8: =AVERAGEIFS(Backtest!$U$9:$U$264,Backtest!$D$9:$D$264,1) -> 0.082545313 | H8: =TestsUsed -> 24 | I8: =SUM(Backtest!$D$9:$D$264) -> 192 | J8: =RANK(C8,$C$6:$C$8,1) -> 2
B10: Champion (lowest MAPE) | C10: =INDEX($B$6:$B$8,MATCH(MIN($C$6:$C$8),$C$6:$C$8,0)) -> seasonal_naive_drift
B11: Times the drift clip changed a backtest ratio | C11: =COUNTIFS(Backtest!$L$9:$L$264,">"&ClipHigh,Backtest!$D$9:$D$264,1)+COUNTIFS(Backtest!$L$9:$L$264,"<"&ClipLow,Backtest!$D$9:$D$264,1) -> 0 | D11: 0 means the clip never binds in the backtest (it does bind in the real forecast, see the Forecast tab).
B12: Highest raw drift in the backtest | C12: =_xlfn.MAXIFS(Backtest!$L$9:$L$264,Backtest!$D$9:$D$264,1) -> 1.9939602
B14: Error by months ahead: why the horizon matters
B15: Months ahead | C15: seasonal_naive | D15: seasonal_naive_drift | E15: holt_winters_log
B16: =ROW()-ROW($B$15) -> 1 | C16: =AVERAGEIFS(Backtest!$P$9:$P$264,Backtest!$D$9:$D$264,1,Backtest!$B$9:$B$264,$B16) -> 0.41659902 | D16: =AVERAGEIFS(Backtest!$Q$9:$Q$264,Backtest!$D$9:$D$264,1,Backtest!$B$9:$B$264,$B16) -> 0.064570076 | E16: =AVERAGEIFS(Backtest!$R$9:$R$264,Backtest!$D$9:$D$264,1,Backtest!$B$9:$B$264,$B16) -> 0.082601102
B17: =ROW()-ROW($B$15) -> 2 | C17: =AVERAGEIFS(Backtest!$P$9:$P$264,Backtest!$D$9:$D$264,1,Backtest!$B$9:$B$264,$B17) -> 0.41636913 | D17: =AVERAGEIFS(Backtest!$Q$9:$Q$264,Backtest!$D$9:$D$264,1,Backtest!$B$9:$B$264,$B17) -> 0.065695992 | E17: =AVERAGEIFS(Backtest!$R$9:$R$264,Backtest!$D$9:$D$264,1,Backtest!$B$9:$B$264,$B17) -> 0.13481126
B18: =ROW()-ROW($B$15) -> 3 | C18: =AVERAGEIFS(Backtest!$P$9:$P$264,Backtest!$D$9:$D$264,1,Backtest!$B$9:$B$264,$B18) -> 0.41886936 | D18: =AVERAGEIFS(Backtest!$Q$9:$Q$264,Backtest!$D$9:$D$264,1,Backtest!$B$9:$B$264,$B18) -> 0.058963697 | E18: =AVERAGEIFS(Backtest!$R$9:$R$264,Backtest!$D$9:$D$264,1,Backtest!$B$9:$B$264,$B18) -> 0.1754759
B19: =ROW()-ROW($B$15) -> 4 | C19: =AVERAGEIFS(Backtest!$P$9:$P$264,Backtest!$D$9:$D$264,1,Backtest!$B$9:$B$264,$B19) -> 0.42088306 | D19: =AVERAGEIFS(Backtest!$Q$9:$Q$264,Backtest!$D$9:$D$264,1,Backtest!$B$9:$B$264,$B19) -> 0.078909365 | E19: =AVERAGEIFS(Backtest!$R$9:$R$264,Backtest!$D$9:$D$264,1,Backtest!$B$9:$B$264,$B19) -> 0.22306177
B20: =ROW()-ROW($B$15) -> 5 | C20: =AVERAGEIFS(Backtest!$P$9:$P$264,Backtest!$D$9:$D$264,1,Backtest!$B$9:$B$264,$B20) -> 0.42104539 | D20: =AVERAGEIFS(Backtest!$Q$9:$Q$264,Backtest!$D$9:$D$264,1,Backtest!$B$9:$B$264,$B20) -> 0.072840692 | E20: =AVERAGEIFS(Backtest!$R$9:$R$264,Backtest!$D$9:$D$264,1,Backtest!$B$9:$B$264,$B20) -> 0.29018289
B21: =ROW()-ROW($B$15) -> 6 | C21: =AVERAGEIFS(Backtest!$P$9:$P$264,Backtest!$D$9:$D$264,1,Backtest!$B$9:$B$264,$B21) -> 0.42687151 | D21: =AVERAGEIFS(Backtest!$Q$9:$Q$264,Backtest!$D$9:$D$264,1,Backtest!$B$9:$B$264,$B21) -> 0.080449102 | E21: =AVERAGEIFS(Backtest!$R$9:$R$264,Backtest!$D$9:$D$264,1,Backtest!$B$9:$B$264,$B21) -> 0.34702435
B22: =ROW()-ROW($B$15) -> 7 | C22: =AVERAGEIFS(Backtest!$P$9:$P$264,Backtest!$D$9:$D$264,1,Backtest!$B$9:$B$264,$B22) -> 0.43072606 | D22: =AVERAGEIFS(Backtest!$Q$9:$Q$264,Backtest!$D$9:$D$264,1,Backtest!$B$9:$B$264,$B22) -> 0.10347269 | E22: =AVERAGEIFS(Backtest!$R$9:$R$264,Backtest!$D$9:$D$264,1,Backtest!$B$9:$B$264,$B22) -> 0.38973026
B23: =ROW()-ROW($B$15) -> 8 | C23: =AVERAGEIFS(Backtest!$P$9:$P$264,Backtest!$D$9:$D$264,1,Backtest!$B$9:$B$264,$B23) -> 0.44208002 | D23: =AVERAGEIFS(Backtest!$Q$9:$Q$264,Backtest!$D$9:$D$264,1,Backtest!$B$9:$B$264,$B23) -> 0.11529421 | E23: =AVERAGEIFS(Backtest!$R$9:$R$264,Backtest!$D$9:$D$264,1,Backtest!$B$9:$B$264,$B23) -> 0.43512759
B24: The old version only looked at row 1 of this table. The real forecast is used at row 8, where the models are far apart.
B27: Error by test: is the winner the winner everywhere?
B28: Possible test | C28: Used as test # | D28: Test starts | E28: History months | F28: seasonal_naive | G28: seasonal_naive_drift | H28: holt_winters_log | I28: Better of drift / HW
B29: =ROW()-ROW($B$28) -> 1 | C29: =INDEX(Backtest!$E$9:$E$264,(B29-1)*Horizon+1) | D29: =INDEX(Backtest!$G$9:$G$264,(B29-1)*Horizon+1) -> 44228 | E29: =INDEX(Backtest!$F$9:$F$264,(B29-1)*Horizon+1) -> 25 | F29: =AVERAGEIFS(Backtest!$P$9:$P$264,Backtest!$A$9:$A$264,$B29) -> 0.48695032 | G29: =AVERAGEIFS(Backtest!$Q$9:$Q$264,Backtest!$A$9:$A$264,$B29) -> 0.10796355 | H29: =AVERAGEIFS(Backtest!$R$9:$R$264,Backtest!$A$9:$A$264,$B29) -> 1.8766436 | I29: =IF(G29<=H29,"Drift","Holt-Winters") -> Drift
B30: =ROW()-ROW($B$28) -> 2 | C30: =INDEX(Backtest!$E$9:$E$264,(B30-1)*Horizon+1) | D30: =INDEX(Backtest!$G$9:$G$264,(B30-1)*Horizon+1) -> 44256 | E30: =INDEX(Backtest!$F$9:$F$264,(B30-1)*Horizon+1) -> 26 | F30: =AVERAGEIFS(Backtest!$P$9:$P$264,Backtest!$A$9:$A$264,$B30) -> 0.47575469 | G30: =AVERAGEIFS(Backtest!$Q$9:$Q$264,Backtest!$A$9:$A$264,$B30) -> 0.16617464 | H30: =AVERAGEIFS(Backtest!$R$9:$R$264,Backtest!$A$9:$A$264,$B30) -> 1.3455798 | I30: =IF(G30<=H30,"Drift","Holt-Winters") -> Drift
B31: =ROW()-ROW($B$28) -> 3 | C31: =INDEX(Backtest!$E$9:$E$264,(B31-1)*Horizon+1) | D31: =INDEX(Backtest!$G$9:$G$264,(B31-1)*Horizon+1) -> 44287 | E31: =INDEX(Backtest!$F$9:$F$264,(B31-1)*Horizon+1) -> 27 | F31: =AVERAGEIFS(Backtest!$P$9:$P$264,Backtest!$A$9:$A$264,$B31) -> 0.47241857 | G31: =AVERAGEIFS(Backtest!$Q$9:$Q$264,Backtest!$A$9:$A$264,$B31) -> 0.068981516 | H31: =AVERAGEIFS(Backtest!$R$9:$R$264,Backtest!$A$9:$A$264,$B31) -> 0.29561628 | I31: =IF(G31<=H31,"Drift","Holt-Winters") -> Drift
B32: =ROW()-ROW($B$28) -> 4 | C32: =INDEX(Backtest!$E$9:$E$264,(B32-1)*Horizon+1) | D32: =INDEX(Backtest!$G$9:$G$264,(B32-1)*Horizon+1) -> 44317 | E32: =INDEX(Backtest!$F$9:$F$264,(B32-1)*Horizon+1) -> 28 | F32: =AVERAGEIFS(Backtest!$P$9:$P$264,Backtest!$A$9:$A$264,$B32) -> 0.46620147 | G32: =AVERAGEIFS(Backtest!$Q$9:$Q$264,Backtest!$A$9:$A$264,$B32) -> 0.090101717 | H32: =AVERAGEIFS(Backtest!$R$9:$R$264,Backtest!$A$9:$A$264,$B32) -> 0.40933568 | I32: =IF(G32<=H32,"Drift","Holt-Winters") -> Drift
B33: =ROW()-ROW($B$28) -> 5 | C33: =INDEX(Backtest!$E$9:$E$264,(B33-1)*Horizon+1) | D33: =INDEX(Backtest!$G$9:$G$264,(B33-1)*Horizon+1) -> 44348 | E33: =INDEX(Backtest!$F$9:$F$264,(B33-1)*Horizon+1) -> 29 | F33: =AVERAGEIFS(Backtest!$P$9:$P$264,Backtest!$A$9:$A$264,$B33) -> 0.46011887 | G33: =AVERAGEIFS(Backtest!$Q$9:$Q$264,Backtest!$A$9:$A$264,$B33) -> 0.093747339 | H33: =AVERAGEIFS(Backtest!$R$9:$R$264,Backtest!$A$9:$A$264,$B33) -> 0.39407811 | I33: =IF(G33<=H33,"Drift","Holt-Winters") -> Drift
B34: =ROW()-ROW($B$28) -> 6 | C34: =INDEX(Backtest!$E$9:$E$264,(B34-1)*Horizon+1) | D34: =INDEX(Backtest!$G$9:$G$264,(B34-1)*Horizon+1) -> 44378 | E34: =INDEX(Backtest!$F$9:$F$264,(B34-1)*Horizon+1) -> 30 | F34: =AVERAGEIFS(Backtest!$P$9:$P$264,Backtest!$A$9:$A$264,$B34) -> 0.44843207 | G34: =AVERAGEIFS(Backtest!$Q$9:$Q$264,Backtest!$A$9:$A$264,$B34) -> 0.13817026 | H34: =AVERAGEIFS(Backtest!$R$9:$R$264,Backtest!$A$9:$A$264,$B34) -> 0.36982032 | I34: =IF(G34<=H34,"Drift","Holt-Winters") -> Drift
B35: =ROW()-ROW($B$28) -> 7 | C35: =INDEX(Backtest!$E$9:$E$264,(B35-1)*Horizon+1) | D35: =INDEX(Backtest!$G$9:$G$264,(B35-1)*Horizon+1) -> 44409 | E35: =INDEX(Backtest!$F$9:$F$264,(B35-1)*Horizon+1) -> 31 | F35: =AVERAGEIFS(Backtest!$P$9:$P$264,Backtest!$A$9:$A$264,$B35) -> 0.45369986 | G35: =AVERAGEIFS(Backtest!$Q$9:$Q$264,Backtest!$A$9:$A$264,$B35) -> 0.045571377 | H35: =AVERAGEIFS(Backtest!$R$9:$R$264,Backtest!$A$9:$A$264,$B35) -> 0.3396295 | I35: =IF(G35<=H35,"Drift","Holt-Winters") -> Drift
B36: =ROW()-ROW($B$28) -> 8 | C36: =INDEX(Backtest!$E$9:$E$264,(B36-1)*Horizon+1) | D36: =INDEX(Backtest!$G$9:$G$264,(B36-1)*Horizon+1) -> 44440 | E36: =INDEX(Backtest!$F$9:$F$264,(B36-1)*Horizon+1) -> 32 | F36: =AVERAGEIFS(Backtest!$P$9:$P$264,Backtest!$A$9:$A$264,$B36) -> 0.44745482 | G36: =AVERAGEIFS(Backtest!$Q$9:$Q$264,Backtest!$A$9:$A$264,$B36) -> 0.063687368 | H36: =AVERAGEIFS(Backtest!$R$9:$R$264,Backtest!$A$9:$A$264,$B36) -> 0.41116534 | I36: =IF(G36<=H36,"Drift","Holt-Winters") -> Drift
B37: =ROW()-ROW($B$28) -> 9 | C37: =INDEX(Backtest!$E$9:$E$264,(B37-1)*Horizon+1) -> 1 | D37: =INDEX(Backtest!$G$9:$G$264,(B37-1)*Horizon+1) -> 44470 | E37: =INDEX(Backtest!$F$9:$F$264,(B37-1)*Horizon+1) -> 33 | F37: =AVERAGEIFS(Backtest!$P$9:$P$264,Backtest!$A$9:$A$264,$B37) -> 0.43283485 | G37: =AVERAGEIFS(Backtest!$Q$9:$Q$264,Backtest!$A$9:$A$264,$B37) -> 0.13090475 | H37: =AVERAGEIFS(Backtest!$R$9:$R$264,Backtest!$A$9:$A$264,$B37) -> 0.69159433 | I37: =IF(G37<=H37,"Drift","Holt-Winters") -> Drift
B38: =ROW()-ROW($B$28) -> 10 | C38: =INDEX(Backtest!$E$9:$E$264,(B38-1)*Horizon+1) -> 2 | D38: =INDEX(Backtest!$G$9:$G$264,(B38-1)*Horizon+1) -> 44501 | E38: =INDEX(Backtest!$F$9:$F$264,(B38-1)*Horizon+1) -> 34 | F38: =AVERAGEIFS(Backtest!$P$9:$P$264,Backtest!$A$9:$A$264,$B38) -> 0.43005698 | G38: =AVERAGEIFS(Backtest!$Q$9:$Q$264,Backtest!$A$9:$A$264,$B38) -> 0.070143383 | H38: =AVERAGEIFS(Backtest!$R$9:$R$264,Backtest!$A$9:$A$264,$B38) -> 0.69412154 | I38: =IF(G38<=H38,"Drift","Holt-Winters") -> Drift
B39: =ROW()-ROW($B$28) -> 11 | C39: =INDEX(Backtest!$E$9:$E$264,(B39-1)*Horizon+1) -> 3 | D39: =INDEX(Backtest!$G$9:$G$264,(B39-1)*Horizon+1) -> 44531 | E39: =INDEX(Backtest!$F$9:$F$264,(B39-1)*Horizon+1) -> 35 | F39: =AVERAGEIFS(Backtest!$P$9:$P$264,Backtest!$A$9:$A$264,$B39) -> 0.42984902 | G39: =AVERAGEIFS(Backtest!$Q$9:$Q$264,Backtest!$A$9:$A$264,$B39) -> 0.053844299 | H39: =AVERAGEIFS(Backtest!$R$9:$R$264,Backtest!$A$9:$A$264,$B39) -> 0.088991579 | I39: =IF(G39<=H39,"Drift","Holt-Winters") -> Drift
B40: =ROW()-ROW($B$28) -> 12 | C40: =INDEX(Backtest!$E$9:$E$264,(B40-1)*Horizon+1) -> 4 | D40: =INDEX(Backtest!$G$9:$G$264,(B40-1)*Horizon+1) -> 44562 | E40: =INDEX(Backtest!$F$9:$F$264,(B40-1)*Horizon+1) -> 36 | F40: =AVERAGEIFS(Backtest!$P$9:$P$264,Backtest!$A$9:$A$264,$B40) -> 0.42707864 | G40: =AVERAGEIFS(Backtest!$Q$9:$Q$264,Backtest!$A$9:$A$264,$B40) -> 0.072897323 | H40: =AVERAGEIFS(Backtest!$R$9:$R$264,Backtest!$A$9:$A$264,$B40) -> 0.11101514 | I40: =IF(G40<=H40,"Drift","Holt-Winters") -> Drift
... B60: =ROW()-ROW($B$28) -> 32 | C60: =INDEX(Backtest!$E$9:$E$264,(B60-1)*Horizon+1) -> 24 | D60: =INDEX(Backtest!$G$9:$G$264,(B60-1)*Horizon+1) -> 45170 | E60: =INDEX(Backtest!$F$9:$F$264,(B60-1)*Horizon+1) -> 56 | F60: =AVERAGEIFS(Backtest!$P$9:$P$264,Backtest!$A$9:$A$264,$B60) -> 0.5207602 | G60: =AVERAGEIFS(Backtest!$Q$9:$Q$264,Backtest!$A$9:$A$264,$B60) -> 0.172899 | H60: =AVERAGEIFS(Backtest!$R$9:$R$264,Backtest!$A$9:$A$264,$B60) -> 0.076806143 | I60: =IF(G60<=H60,"Drift","Holt-Winters") -> Holt-Winters
B62: Grey rows are tests skipped by Settings. Drift wins on average, but Holt-Winters wins several recent tests, when growth was speeding up.

Sheet OldDesign
A1: Step 6 · The old design: 6 tests, 1 month ahead each
A2: The first version of src/forecasting.py checked each model only one month ahead, on the last 6 months (docs/forecast_review.md, check 1).
A3: Same formulas as the Backtest tab, but only step 1 and only 6 tests. The real forecast runs 8 months ahead, so this tested the wrong thing.
B5: Tests | C5: 6 | D5: Fixed at 6: Python predictions exist only for these 6 tests.
B8: Test | C8: Offset | D8: History months | E8: Forecast month | F8: Actual | G8: Seasonal naive | H8: Raw drift | I8: Clipped drift | J8: Drift forecast | K8: Holt-Winters (Python) | L8: Error naive | M8: Error drift | N8: Error HW | O8: Winner (drift vs HW)
B9: =ROW()-ROW($B$8) -> 1 | C9: =$C$5-B9+1 -> 6 | D9: =NMonths-C9 -> 58 | E9: =INDEX(Months,D9+1) -> 45231 | F9: =INDEX(Sales,D9+1) -> 298467.68 | G9: =INDEX(Sales,D9+1-Season) -> 155504.04 | H9: =INDEX(Sales,D9)/INDEX(Sales,D9-Season) -> 1.8361253 | I9: =MIN(MAX(H9,ClipLow),ClipHigh) -> 1.8361253 | J9: =G9*I9 -> 285524.9 | K9: =INDEX(HWOld,MATCH(C9,HWOldOffsets,0)) -> 299376.07 | L9: =ABS(G9-F9)/F9 -> 0.47899203 | M9: =ABS(J9-F9)/F9 -> 0.04336409 | N9: =ABS(K9-F9)/F9 -> 0.0030435274 | O9: =IF(M9<N9,"Drift","Holt-Winters") -> Holt-Winters
B10: =ROW()-ROW($B$8) -> 2 | C10: =$C$5-B10+1 -> 5 | D10: =NMonths-C10 -> 59 | E10: =INDEX(Months,D10+1) -> 45261 | F10: =INDEX(Sales,D10+1) -> 326301.66 | G10: =INDEX(Sales,D10+1-Season) -> 160734.27 | H10: =INDEX(Sales,D10)/INDEX(Sales,D10-Season) -> 1.9193564 | I10: =MIN(MAX(H10,ClipLow),ClipHigh) -> 1.9193564 | J10: =G10*I10 -> 308506.36 | K10: =INDEX(HWOld,MATCH(C10,HWOldOffsets,0)) -> 308795.32 | L10: =ABS(G10-F10)/F10 -> 0.50740591 | M10: =ABS(J10-F10)/F10 -> 0.054536359 | N10: =ABS(K10-F10)/F10 -> 0.05365078 | O10: =IF(M10<N10,"Drift","Holt-Winters") -> Holt-Winters
B11: =ROW()-ROW($B$8) -> 3 | C11: =$C$5-B11+1 -> 4 | D11: =NMonths-C11 -> 60 | E11: =INDEX(Months,D11+1) -> 45292 | F11: =INDEX(Sales,D11+1) -> 348737.74 | G11: =INDEX(Sales,D11+1-Season) -> 188680.17 | H11: =INDEX(Sales,D11)/INDEX(Sales,D11-Season) -> 2.030069 | I11: =MIN(MAX(H11,ClipLow),ClipHigh) -> 2.030069 | J11: =G11*I11 -> 383033.77 | K11: =INDEX(HWOld,MATCH(C11,HWOldOffsets,0)) -> 406969.85 | L11: =ABS(G11-F11)/F11 -> 0.45896257 | M11: =ABS(J11-F11)/F11 -> 0.098343315 | N11: =ABS(K11-F11)/F11 -> 0.16697965 | O11: =IF(M11<N11,"Drift","Holt-Winters") -> Drift
B12: =ROW()-ROW($B$8) -> 4 | C12: =$C$5-B12+1 -> 3 | D12: =NMonths-C12 -> 61 | E12: =INDEX(Months,D12+1) -> 45323 | F12: =INDEX(Sales,D12+1) -> 381972.6 | G12: =INDEX(Sales,D12+1-Season) -> 167409.85 | H12: =INDEX(Sales,D12)/INDEX(Sales,D12-Season) -> 1.848301 | I12: =MIN(MAX(H12,ClipLow),ClipHigh) -> 1.848301 | J12: =G12*I12 -> 309423.79 | K12: =INDEX(HWOld,MATCH(C12,HWOldOffsets,0)) -> 307438.66 | L12: =ABS(G12-F12)/F12 -> 0.56172288 | M12: =ABS(J12-F12)/F12 -> 0.18993198 | N12: =ABS(K12-F12)/F12 -> 0.19512902 | O12: =IF(M12<N12,"Drift","Holt-Winters") -> Drift
B13: =ROW()-ROW($B$8) -> 5 | C13: =$C$5-B13+1 -> 2 | D13: =NMonths-C13 -> 62 | E13: =INDEX(Months,D13+1) -> 45352 | F13: =INDEX(Sales,D13+1) -> 441334.21 | G13: =INDEX(Sales,D13+1-Season) -> 184777.9 | H13: =INDEX(Sales,D13)/INDEX(Sales,D13-Season) -> 2.2816614 | I13: =MIN(MAX(H13,ClipLow),ClipHigh) -> 2.2816614 | J13: =G13*I13 -> 421600.61 | K13: =INDEX(HWOld,MATCH(C13,HWOldOffsets,0)) -> 551176.32 | L13: =ABS(G13-F13)/F13 -> 0.58131979 | M13: =ABS(J13-F13)/F13 -> 0.044713507 | N13: =ABS(K13-F13)/F13 -> 0.24888646 | O13: =IF(M13<N13,"Drift","Holt-Winters") -> Drift
B14: =ROW()-ROW($B$8) -> 6 | C14: =$C$5-B14+1 -> 1 | D14: =NMonths-C14 -> 63 | E14: =INDEX(Months,D14+1) -> 45383 | F14: =INDEX(Sales,D14+1) -> 550157.88 | G14: =INDEX(Sales,D14+1-Season) -> 193149.96 | H14: =INDEX(Sales,D14)/INDEX(Sales,D14-Season) -> 2.3884578 | I14: =MIN(MAX(H14,ClipLow),ClipHigh) -> 2.3884578 | J14: =G14*I14 -> 461330.52 | K14: =INDEX(HWOld,MATCH(C14,HWOldOffsets,0)) -> 476681.42 | L14: =ABS(G14-F14)/F14 -> 0.64891903 | M14: =ABS(J14-F14)/F14 -> 0.16145794 | N14: =ABS(K14-F14)/F14 -> 0.13355523 | O14: =IF(M14<N14,"Drift","Holt-Winters") -> Holt-Winters
B15: Average (MAPE) | L15: =AVERAGE(L9:L14) -> 0.5395537 | M15: =AVERAGE(M9:M14) -> 0.098724532 | N15: =AVERAGE(N9:N14) -> 0.13354078
B16: Drift wins | E16: =COUNTIF(O9:O14,"Drift") -> 3 | F16: A 3–3 split: six results cannot tell the models apart.
B17: Holt-Winters wins | E17: =COUNTIF(O9:O14,"Holt-Winters") -> 3
B20: Old vs new, side by side
E21: Old design | F21: New design
B22: Tests | E22: =C5 -> 6 | F22: =TestsUsed -> 24
B23: Months checked per test | E23: 1 | F23: =Horizon -> 8
B24: Total checks (folds) | E24: =C5*E23 -> 6 | F24: =Scores!I7 -> 192
B25: Drift MAPE | E25: =M15 -> 0.098724532 | F25: =Scores!C7 -> 0.080024478
B26: Holt-Winters MAPE | E26: =N15 -> 0.13354078 | F26: =Scores!C8 -> 0.25975189

Sheet Forecast
A1: Step 7 · The real forecast: May to December 2024
A2: Now the champion is run once on all 64 months. No checking is possible: these months are the future.
A3: The drift ratio uses April 2024 ÷ April 2023. Watch whether the clip changes it.
B5: Champion model (from Scores) | C5: =Champion -> seasonal_naive_drift
B6: Last actual month | C6: =LastMonth -> 45383
B7: Latest month sales | C7: =INDEX(Sales,NMonths) -> 550157.88
B8: Same month one year earlier | C8: =INDEX(Sales,NMonths-Season) -> 193149.96
B9: Raw drift = latest ÷ year earlier | C9: =C7/C8 -> 2.8483458
B10: Drift after clip | C10: =MIN(MAX(C9,ClipLow),ClipHigh) -> 2.5
B11: Is the clip active? | C11: =IF(C9<>C10,"Yes: the cap changes the forecast","No") -> Yes: the cap changes the forecast
B12: Forecast month. | C12: 1 = May 2024. | D12: INDEX(Sales, N + step − 12). | E12: Same month last year. | F12: Same month last year × clipped drift. | G12: From HW_Python. | H12: The column whose header matches the champion. | I12: Same month last year × raw drift. | J12: How much higher without the clip.
B13: Month | C13: Steps ahead | D13: Same month last year | E13: seasonal_naive | F13: seasonal_naive_drift | G13: holt_winters_log | H13: Chosen forecast | I13: Drift without the clip | J13: Clip effect
B14: =EDATE($C$6,C14) -> 45413 | C14: =ROW()-ROW($C$13) -> 1 | D14: =INDEX(Sales,NMonths+C14-Season) -> 209624.34 | E14: =D14 -> 209624.34 | F14: =D14*$C$10 -> 524060.85 | G14: =INDEX(HWProd,C14) -> 587529.42 | H14: =INDEX(E14:G14,MATCH($C$5,$E$13:$G$13,0)) -> 524060.85 | I14: =D14*$C$9 -> 597082.61 | J14: =I14/H14-1 -> 0.13933833
B15: =EDATE($C$6,C15) -> 45444 | C15: =ROW()-ROW($C$13) -> 2 | D15: =INDEX(Sales,NMonths+C15-Season) -> 205503.24 | E15: =D15 -> 205503.24 | F15: =D15*$C$10 -> 513758.1 | G15: =INDEX(HWProd,C15) -> 656018.61 | H15: =INDEX(E15:G15,MATCH($C$5,$E$13:$G$13,0)) -> 513758.1 | I15: =D15*$C$9 -> 585344.29 | J15: =I15/H15-1 -> 0.13933833
B16: =EDATE($C$6,C16) -> 45474 | C16: =ROW()-ROW($C$13) -> 3 | D16: =INDEX(Sales,NMonths+C16-Season) -> 232777.64 | E16: =D16 -> 232777.64 | F16: =D16*$C$10 -> 581944.1 | G16: =INDEX(HWProd,C16) -> 788823.78 | H16: =INDEX(E16:G16,MATCH($C$5,$E$13:$G$13,0)) -> 581944.1 | I16: =D16*$C$9 -> 663031.22 | J16: =I16/H16-1 -> 0.13933833
B17: =EDATE($C$6,C17) -> 45505 | C17: =ROW()-ROW($C$13) -> 4 | D17: =INDEX(Sales,NMonths+C17-Season) -> 246129.77 | E17: =D17 -> 246129.77 | F17: =D17*$C$10 -> 615324.43 | G17: =INDEX(HWProd,C17) -> 894566.13 | H17: =INDEX(E17:G17,MATCH($C$5,$E$13:$G$13,0)) -> 615324.43 | I17: =D17*$C$9 -> 701062.7 | J17: =I17/H17-1 -> 0.13933833
B18: =EDATE($C$6,C18) -> 45536 | C18: =ROW()-ROW($C$13) -> 5 | D18: =INDEX(Sales,NMonths+C18-Season) -> 261138.52 | E18: =D18 -> 261138.52 | F18: =D18*$C$10 -> 652846.3 | G18: =INDEX(HWProd,C18) -> 980272.25 | H18: =INDEX(E18:G18,MATCH($C$5,$E$13:$G$13,0)) -> 652846.3 | I18: =D18*$C$9 -> 743812.81 | J18: =I18/H18-1 -> 0.13933833
B19: =EDATE($C$6,C19) -> 45566 | C19: =ROW()-ROW($C$13) -> 6 | D19: =INDEX(Sales,NMonths+C19-Season) -> 279981.62 | E19: =D19 -> 279981.62 | F19: =D19*$C$10 -> 699954.05 | G19: =INDEX(HWProd,C19) -> 1206104 | H19: =INDEX(E19:G19,MATCH($C$5,$E$13:$G$13,0)) -> 699954.05 | I19: =D19*$C$9 -> 797484.48 | J19: =I19/H19-1 -> 0.13933833
B20: =EDATE($C$6,C20) -> 45597 | C20: =ROW()-ROW($C$13) -> 7 | D20: =INDEX(Sales,NMonths+C20-Season) -> 298467.68 | E20: =D20 -> 298467.68 | F20: =D20*$C$10 -> 746169.2 | G20: =INDEX(HWProd,C20) -> 1423601.4 | H20: =INDEX(E20:G20,MATCH($C$5,$E$13:$G$13,0)) -> 746169.2 | I20: =D20*$C$9 -> 850139.17 | J20: =I20/H20-1 -> 0.13933833
B21: =EDATE($C$6,C21) -> 45627 | C21: =ROW()-ROW($C$13) -> 8 | D21: =INDEX(Sales,NMonths+C21-Season) -> 326301.66 | E21: =D21 -> 326301.66 | F21: =D21*$C$10 -> 815754.15 | G21: =INDEX(HWProd,C21) -> 1647845.8 | H21: =INDEX(E21:G21,MATCH($C$5,$E$13:$G$13,0)) -> 815754.15 | I21: =D21*$C$9 -> 929419.97 | J21: =I21/H21-1 -> 0.13933833
B22: Total, 8 months | D22: =SUM(D14:D21) -> 2059924.5 | E22: =SUM(E14:E21) -> 2059924.5 | F22: =SUM(F14:F21) -> 5149811.2 | G22: =SUM(G14:G21) -> 8184761.3 | H22: =SUM(H14:H21) -> 5149811.2 | I22: =SUM(I14:I21) -> 5867377.3 | J22: =I22/H22-1 -> 0.13933833
B24: Python: point_forecast = MODELS[champion](series, horizon) in run(), lines 249–251.

Sheet Scenarios
A1: Step 8 · Scenarios: a range instead of one number
A2: Each scenario scales the chosen forecast by a volume multiplier and adjusts the latest net margin. Profit = sales × margin.
A3: The multipliers and margin changes live in Settings (rows 18 to 20).
B5: Latest net margin (Apr 2024) | C5: =INDEX(Margin,NMonths) -> 0.51848983
B6: Volume multiplier | D6: =Settings!$C$18 -> 1 | E6: =Settings!$C$19 -> 1.1 | F6: =Settings!$C$20 -> 0.9
B7: Assumed net margin | G7: =$C$5+Settings!$D$18/100 -> 0.51848983 | H7: =$C$5+Settings!$D$19/100 -> 0.52348983 | I7: =$C$5+Settings!$D$20/100 -> 0.49848983
B8: Month | C8: Chosen forecast | D8: Base sales | E8: Upside sales | F8: Downside sales | G8: Base profit | H8: Upside profit | I8: Downside profit
B9: =Forecast!B14 -> 45413 | C9: =Forecast!H14 -> 524060.85 | D9: =$C9*D$6 -> 524060.85 | E9: =$C9*E$6 -> 576466.94 | F9: =$C9*F$6 -> 471654.77 | G9: =D9*G$7 -> 271720.22 | H9: =E9*H$7 -> 301774.58 | I9: =F9*I$7 -> 235115.1
B10: =Forecast!B15 -> 45444 | C10: =Forecast!H15 -> 513758.1 | D10: =$C10*D$6 -> 513758.1 | E10: =$C10*E$6 -> 565133.91 | F10: =$C10*F$6 -> 462382.29 | G10: =D10*G$7 -> 266378.35 | H10: =E10*H$7 -> 295841.85 | I10: =F10*I$7 -> 230492.87
B11: =Forecast!B16 -> 45474 | C11: =Forecast!H16 -> 581944.1 | D11: =$C11*D$6 -> 581944.1 | E11: =$C11*E$6 -> 640138.51 | F11: =$C11*F$6 -> 523749.69 | G11: =D11*G$7 -> 301732.1 | H11: =E11*H$7 -> 335106 | I11: =F11*I$7 -> 261083.89
B12: =Forecast!B17 -> 45505 | C12: =Forecast!H17 -> 615324.43 | D12: =$C12*D$6 -> 615324.43 | E12: =$C12*E$6 -> 676856.87 | F12: =$C12*F$6 -> 553791.98 | G12: =D12*G$7 -> 319039.45 | H12: =E12*H$7 -> 354327.68 | I12: =F12*I$7 -> 276059.67
B13: =Forecast!B18 -> 45536 | C13: =Forecast!H18 -> 652846.3 | D13: =$C13*D$6 -> 652846.3 | E13: =$C13*E$6 -> 718130.93 | F13: =$C13*F$6 -> 587561.67 | G13: =D13*G$7 -> 338494.16 | H13: =E13*H$7 -> 375934.24 | I13: =F13*I$7 -> 292893.51
B14: =Forecast!B19 -> 45566 | C14: =Forecast!H19 -> 699954.05 | D14: =$C14*D$6 -> 699954.05 | E14: =$C14*E$6 -> 769949.46 | F14: =$C14*F$6 -> 629958.65 | G14: =D14*G$7 -> 362919.05 | H14: =E14*H$7 -> 403060.71 | I14: =F14*I$7 -> 314027.98
B15: =Forecast!B20 -> 45597 | C15: =Forecast!H20 -> 746169.2 | D15: =$C15*D$6 -> 746169.2 | E15: =$C15*E$6 -> 820786.12 | F15: =$C15*F$6 -> 671552.28 | G15: =D15*G$7 -> 386881.14 | H15: =E15*H$7 -> 429673.18 | I15: =F15*I$7 -> 334761.98
B16: =Forecast!B21 -> 45627 | C16: =Forecast!H21 -> 815754.15 | D16: =$C16*D$6 -> 815754.15 | E16: =$C16*E$6 -> 897329.57 | F16: =$C16*F$6 -> 734178.74 | G16: =D16*G$7 -> 422960.23 | H16: =E16*H$7 -> 469742.9 | I16: =F16*I$7 -> 365980.63
B17: Total, 8 months | C17: =SUM(C9:C16) -> 5149811.2 | D17: =SUM(D9:D16) -> 5149811.2 | E17: =SUM(E9:E16) -> 5664792.3 | F17: =SUM(F9:F16) -> 4634830.1 | G17: =SUM(G9:G16) -> 2670124.7 | H17: =SUM(H9:H16) -> 2965461.1 | I17: =SUM(I9:I16) -> 2310415.6
B20: Summary
B21: Scenario | C21: Net sales | D21: Net profit | E21: Assumed margin | F21: Volume multiplier | G21: Assumption
B22: Base | C22: =D17 -> 5149811.2 | D22: =G17 -> 2670124.7 | E22: =G7 -> 0.51848983 | F22: =D6 -> 1 | G22: =Settings!$E$18 -> Current trend continues; no change to pricing or promotion intensity.
B23: Upside | C23: =E17 -> 5664792.3 | D23: =H17 -> 2965461.1 | E23: =H7 -> 0.52348983 | F23: =E6 -> 1.1 | G23: =Settings!$E$19 -> Peak-season sell-through runs 10% ahead with a modest mix benefit.
B24: Downside | C24: =F17 -> 4634830.1 | D24: =I17 -> 2310415.6 | E24: =I7 -> 0.49848983 | F24: =F6 -> 0.9 | G24: =Settings!$E$20 -> Demand softens 10% and clearing aged stock costs 2 points of margin.

Sheet CountrySplit
A1: Step 9 · Split the forecast by country (top-down)
A2: Forecast the whole business once, then give each country its share of the last 6 complete months of sales.
A3: Source for the blue values: mart.actual_country_month. Small markets have too little history for their own seasonal model.
B6: Country | C6: Nov 2023 | D6: Dec 2023 | E6: Jan 2024 | F6: Feb 2024 | G6: Mar 2024 | H6: Apr 2024 | I6: Last 6 months | J6: Share
B7: China | C7: 104507.24 | D7: 112846.56 | E7: 115628.38 | F7: 124008.68 | G7: 152428.92 | H7: 185531.85 | I7: =SUM(C7:H7) -> 794951.63 | J7: =I7/$I$20 -> 0.33871376
B8: United States | C8: 67673.56 | D8: 73608.11 | E8: 82828.4 | F8: 83745.67 | G8: 96724.07 | H8: 130406.39 | I8: =SUM(C8:H8) -> 534986.2 | J8: =I8/$I$20 -> 0.22794744
B9: Brazil | C9: 38990.74 | D9: 44368.47 | E9: 46614.56 | F9: 53390.01 | G9: 62326.49 | H9: 80200.83 | I9: =SUM(C9:H9) -> 325891.1 | J9: =I9/$I$20 -> 0.13885599
B10: South Korea | C10: 15628.19 | D10: 17468.07 | E10: 20951.51 | F10: 23463.41 | G10: 23242.25 | H10: 29344.84 | I10: =SUM(C10:H10) -> 130098.27 | J10: =I10/$I$20 -> 0.055432397
B11: France | C11: 16709.82 | D11: 20871.84 | E11: 15112.89 | F11: 18019.73 | G11: 20130.98 | H11: 24033.84 | I11: =SUM(C11:H11) -> 114879.1 | J11: =I11/$I$20 -> 0.048947798
B12: United Kingdom | C12: 14055.34 | D12: 16185.45 | E12: 13212.3 | F12: 20001.2 | G12: 22558.26 | H12: 22325.46 | I12: =SUM(C12:H12) -> 108338.01 | J12: =I12/$I$20 -> 0.046160764
B13: Germany | C13: 11444.9 | D13: 11170.59 | E13: 17645.91 | F13: 15667.58 | G13: 22462.2 | H13: 24779.63 | I13: =SUM(C13:H13) -> 103170.81 | J13: =I13/$I$20 -> 0.043959118
B14: Spain | C14: 11718.39 | D14: 15034.64 | E14: 13330.14 | F14: 12861.7 | G14: 16953.7 | H14: 22331.57 | I14: =SUM(C14:H14) -> 92230.14 | J14: =I14/$I$20 -> 0.039297507
B15: Japan | C15: 6789.77 | D15: 5685.4 | E15: 9202.2 | F15: 10818.26 | G15: 8671.86 | H15: 11898.34 | I15: =SUM(C15:H15) -> 53065.83 | J15: =I15/$I$20 -> 0.02261034
B16: Australia | C16: 6803.09 | D16: 4378.28 | E16: 7915.33 | F16: 12138.22 | G16: 9352.3 | H16: 11187.7 | I16: =SUM(C16:H16) -> 51774.92 | J16: =I16/$I$20 -> 0.022060308
B17: Belgium | C17: 3288.73 | D17: 4131.61 | E17: 4912.89 | F17: 4382.8 | G17: 5609.78 | H17: 6974.58 | I17: =SUM(C17:H17) -> 29300.39 | J17: =I17/$I$20 -> 0.012484339
B18: Poland | C18: 857.91001 | D18: 306.89 | E18: 1383.23 | F18: 3288.56 | G18: 873.40001 | H18: 717.84 | I18: =SUM(C18:H18) -> 7427.83 | J18: =I18/$I$20 -> 0.003164857
B19: Colombia | C19: 0 | D19: 245.75 | E19: 0 | F19: 186.78 | G19: 0 | H19: 425.01 | I19: =SUM(C19:H19) -> 857.54 | J19: =I19/$I$20 -> 0.00036538147
B20: Total | C20: =SUM(C7:C19) -> 298467.68 | D20: =SUM(D7:D19) -> 326301.66 | E20: =SUM(E7:E19) -> 348737.74 | F20: =SUM(F7:F19) -> 381972.6 | G20: =SUM(G7:G19) -> 441334.21 | H20: =SUM(H7:H19) -> 550157.88 | I20: =SUM(I7:I19) -> 2346971.8 | J20: =SUM(J7:J19) -> 1
B23: Allocation: chosen forecast × country share
B24: Country | C24: Share | D24: =INDEX(FcMonths,1) -> 45413 | E24: =INDEX(FcMonths,2) -> 45444 | F24: =INDEX(FcMonths,3) -> 45474 | G24: =INDEX(FcMonths,4) -> 45505 | H24: =INDEX(FcMonths,5) -> 45536 | I24: =INDEX(FcMonths,6) -> 45566 | J24: =INDEX(FcMonths,7) -> 45597 | K24: =INDEX(FcMonths,8) -> 45627
B25: Total forecast | D25: =INDEX(FcChosen,1) -> 524060.85 | E25: =INDEX(FcChosen,2) -> 513758.1 | F25: =INDEX(FcChosen,3) -> 581944.1 | G25: =INDEX(FcChosen,4) -> 615324.43 | H25: =INDEX(FcChosen,5) -> 652846.3 | I25: =INDEX(FcChosen,6) -> 699954.05 | J25: =INDEX(FcChosen,7) -> 746169.2 | K25: =INDEX(FcChosen,8) -> 815754.15
B26: =B7 -> China | C26: =J7 -> 0.33871376 | D26: =D$25*$C26 -> 177506.62 | E26: =E$25*$C26 -> 174016.94 | F26: =F$25*$C26 -> 197112.47 | G26: =G$25*$C26 -> 208418.85 | H26: =H$25*$C26 -> 221128.02 | I26: =I$25*$C26 -> 237084.07 | J26: =J$25*$C26 -> 252737.77 | K26: =K$25*$C26 -> 276307.15
B27: =B8 -> United States | C27: =J8 -> 0.22794744 | D27: =D$25*$C27 -> 119458.33 | E27: =E$25*$C27 -> 117109.84 | F27: =F$25*$C27 -> 132652.67 | G27: =G$25*$C27 -> 140261.63 | H27: =H$25*$C27 -> 148814.64 | I27: =I$25*$C27 -> 159552.73 | J27: =J$25*$C27 -> 170087.36 | K27: =K$25*$C27 -> 185949.07
B28: =B9 -> Brazil | C28: =J9 -> 0.13885599 | D28: =D$25*$C28 -> 72768.991 | E28: =E$25*$C28 -> 71338.392 | F28: =F$25*$C28 -> 80806.427 | G28: =G$25*$C28 -> 85441.485 | H28: =H$25*$C28 -> 90651.623 | I28: =I$25*$C28 -> 97192.816 | J28: =J$25*$C28 -> 103610.07 | K28: =K$25*$C28 -> 113272.35
B29: =B10 -> South Korea | C29: =J10 -> 0.055432397 | D29: =D$25*$C29 -> 29049.949 | E29: =E$25*$C29 -> 28478.843 | F29: =F$25*$C29 -> 32258.556 | G29: =G$25*$C29 -> 34108.908 | H29: =H$25*$C29 -> 36188.835 | I29: =I$25*$C29 -> 38800.131 | J29: =J$25*$C29 -> 41361.947 | K29: =K$25*$C29 -> 45219.208
B30: =B11 -> France | C30: =J11 -> 0.048947798 | D30: =D$25*$C30 -> 25651.625 | E30: =E$25*$C30 -> 25147.328 | F30: =F$25*$C30 -> 28484.882 | G30: =G$25*$C30 -> 30118.776 | H30: =H$25*$C30 -> 31955.389 | I30: =I$25*$C30 -> 34261.209 | J30: =J$25*$C30 -> 36523.339 | K30: =K$25*$C30 -> 39929.369
B31: =B12 -> United Kingdom | C31: =J12 -> 0.046160764 | D31: =D$25*$C31 -> 24191.049 | E31: =E$25*$C31 -> 23715.466 | F31: =F$25*$C31 -> 26862.984 | G31: =G$25*$C31 -> 28403.846 | H31: =H$25*$C31 -> 30135.884 | I31: =I$25*$C31 -> 32310.414 | J31: =J$25*$C31 -> 34443.74 | K31: =K$25*$C31 -> 37655.835
B32: =B13 -> Germany | C32: =J13 -> 0.043959118 | D32: =D$25*$C32 -> 23037.253 | E32: =E$25*$C32 -> 22584.353 | F32: =F$25*$C32 -> 25581.75 | G32: =G$25*$C32 -> 27049.119 | H32: =H$25*$C32 -> 28698.548 | I32: =I$25*$C32 -> 30769.363 | J32: =J$25*$C32 -> 32800.94 | K32: =K$25*$C32 -> 35859.833
